生成器返回的迭代器对象还具有throw()方法。使用这种方法，我们可以通过向生成器中注入一个异常来停止程序

```
function* generate() {
  yield 33;
  yield 99;
}

const go = generate();

const firstStep = go.next().value; // 33

go.throw(Error("我要结束你!"));

const secondStep = go.next().value; // 这里会抛出异常
```

可以使用try/catch捕获异常
```
function* generate() {
  try {
    yield 33;
    yield 99;
  } catch (error) {
    console.error(error.message);
  }
}
```

generator 返回的是一个迭代器对象，除了next以外，for of 也可以向生成器中提取值
```
function* generate() {
  yield 33;
  yield 99;

  throw Error("我要结束你!")
}

try {
  for (const value of generate()) {
    console.log(value)
  }
} catch (error) {
  console.log(error.message)
}
```

#### 异步遍历 for await...of
JavaScript中的async generators是能够生成 Promises 而不是简单值的生成器函数。
```
async function* asyncGenerator() {
  yield 33;
  yield 99;
  throw Error("Something went wrong!"); // Promise.reject
}
```
基于 Promise，此处适用于错误处理的相同规则。在异步生成器中 throw 将会触发 Promise 的reject，我们可以使用catch对其进行拦截。

```

async function* asyncGenerator() {
  yield 33;
  yield 99;
  throw Error("Something went wrong!"); // Promise.reject
}

async function consumer() {
  try {
    for await (const value of asyncGenerator()) {
      console.log(value);
    }
  } catch (error) {
    console.error(error.message);
  }
}

consumer();
```



