```
function failAfterOneSecond() {
  setTimeout(() => {
    throw Error("Something went wrong!");
  }, 1000);
}

try {
  failAfterOneSecond();
} catch (error) {
  console.error(error.message);
}
```

try-catch 无法捕获定时器异常，try--catch是同步的，而定时器是异步的，当执行到定时器回调时try-catch已经跑完了，异常无法捕获到

解决办法可以让try-catch放到回调函数中，但是更推荐的是用promise来解决

#### 使用promise处理定时器异常
```
function failAfterOneSecond() {
  return new Promise((_, reject) => {
    setTimeout(() => {
      reject(Error("Something went wrong!"));
    }, 1000);
  });
}

failAfterOneSecond().catch(reason => console.error(reason.message));
```
