```
function toUppercase(string) {
  if (typeof string !== "string") {
    return Promise.reject(TypeError("Wrong type given, expected a string"));
  }

  const result = string.toUpperCase();

  return Promise.resolve(result);
}
```

使用了 Promise ，所以可以使用 then 来接收返回的内容，或者用 catch 来捕获出现的错误。
```
toUppercase(99)
  .then(result => result)
  .catch(error => console.error(error.message));
	.finally(() => console.log("Run baby, run"));
```

* 使用 Promise.reject 可以很方便的抛出错误：
```
Promise.reject(TypeError("Wrong type given, expected a string"));
```

* 通过抛出异常来退出 Promise。
```
Promise.resolve("A string")
  .then(value => {
    if (typeof value === "string") {
      throw TypeError("Expected a number!");
    }
  })
  .catch(reason => console.log(reason.message));
```

* promise.all
```
const promise1 = Promise.resolve("All good!");
const promise2 = Promise.reject(Error("No good, sorry!"));
const promise3 = Promise.reject(Error("Bad day ..."));

Promise.all([promise1, promise2, promise3])
  .then(results => console.log(results))
  .catch(error => console.error(error.message));
	.finally(() => console.log("Always runs!"));
```

* promise.any
```

const promise1 = Promise.reject(Error("No good, sorry!"));
const promise2 = Promise.reject(Error("Bad day ..."));

Promise.any([promise1, promise2])
  .then(result => console.log(result))
  .catch(error => console.error(error))
  .finally(() => console.log("Always runs!"));

// [Error: "No good, sorry!, Error: "Bad day ..."]
```

* promise.race
```
const promise1 = Promise.resolve("The first!");
const rejection = Promise.reject(Error("Ouch!"));
const promise2 = Promise.resolve("The second!");

Promise.race([rejection, promise1, promise2])
  .then(result => console.log(result))
  .catch(error => console.error(error.message));

// Ouch!
```

* promise.allSettled

Promise.allSettled()方法返回一个在所有给定的promise都已经fulfilled或rejected后的promise，并带有一个对象数组，每个对象表示对应的promise结果。

```
const promise1 = Promise.resolve("Good!");
const promise2 = Promise.reject(Error("No good, sorry!"));

Promise.allSettled([promise1, promise2])
  .then(results => console.log(results))
  .catch(error => console.error(error))
  .finally(() => console.log("Always runs!"));
```
这种情况 catch 不会被执行， finally 永远会执行
```
[
  { status: 'fulfilled', value: 'Good!' },
  {
    status: 'rejected',
    reason: Error: No good, sorry!
  }
]
```

* async/await
async/await可以直接使用try-catch-finally捕获异常，也可以使用promise的方式捕获
